<?xml version="1.0"?>
<robot name="vehicle_blue">

    <!-- chassis -->
    <link name="chassis">
        <inertial>
            <mass value="1.14395"/>
            <inertia ixx="0.095329" ixy="0.0" ixz="0.0" iyy="0.381317" iyz="0.0" izz="0.476646"/>
        </inertial>
        <visual>
            <geometry>
                <box size="2.0 1.0 0.5"/>
            </geometry>
            <material name="blue">
                <color rgba="0 0 1 1"/>
            </material>
        </visual>
        <collision>
            <geometry>
                <box size="2.0 1.0 0.5"/>
            </geometry>
        </collision>
    </link>

    <!-- left wheel -->
    <link name="left_wheel">
        <inertial>
            <mass value="1"/>
            <inertia ixx="0.043333" ixy="0.0" ixz="0.0" iyy="0.043333" iyz="0.0" izz="0.08"/>
        </inertial>
        <visual>
            <geometry>
                <cylinder radius="0.4" length="0.2"/>
            </geometry>
            <material name="red">
                <color rgba="1 0 0 1"/>
            </material>
        </visual>
        <collision>
            <geometry>
                <cylinder radius="0.4" length="0.2"/>
            </geometry>
        </collision>
    </link>

    <!-- right wheel -->
    <link name="right_wheel">
        <inertial>
            <mass value="1"/>
            <inertia ixx="0.043333" ixy="0.0" ixz="0.0" iyy="0.043333" iyz="0.0" izz="0.08"/>
        </inertial>
        <visual>
            <geometry>
                <cylinder radius="0.4" length="0.2"/>
            </geometry>
            <material name="red"/>
        </visual>
        <collision>
            <geometry>
                <cylinder radius="0.4" length="0.2"/>
            </geometry>
        </collision>
    </link>

    <!-- caster -->
    <link name="caster">
        <inertial>
            <mass value="1"/>
            <inertia ixx="0.016" ixy="0.0" ixz="0.0" iyy="0.016" iyz="0.0" izz="0.016"/>
        </inertial>
        <visual>
            <geometry>
                <sphere radius="0.2"/>
            </geometry>
            <material name="green">
                <color rgba="0 1 0 1"/>
            </material>
        </visual>
        <collision>
            <geometry>
                <sphere radius="0.2"/>
            </geometry>
        </collision>
    </link>

    <!-- camera link -->
    <link name="camera_link">
        <inertial>
            <mass value="0.01"/>
            <inertia ixx="1e-5" ixy="0.0" ixz="0.0" iyy="1e-5" iyz="0.0" izz="1e-5"/>
        </inertial>
        <visual>
            <geometry>
                <box size="0.15 0.05 0.05"/>
            </geometry>
            <material name="black">
                <color rgba="0 0 0 1"/>
            </material>
        </visual>
        <collision>
            <geometry>
                <box size="0.1 0.05 0.05"/>
            </geometry>
        </collision>
    </link>

    <!-- joints -->
    <joint name="left_wheel_joint" type="continuous">
        <origin xyz="-0.5 0.6 0" rpy="-1.5708 0 0"/>
        <parent link="chassis"/>
        <child link="left_wheel"/>
        <axis xyz="0 1 0"/>
    </joint>

    <joint name="right_wheel_joint" type="continuous">
        <origin xyz="-0.5 -0.6 0" rpy="-1.5708 0 0"/>
        <parent link="chassis"/>
        <child link="right_wheel"/>
        <axis xyz="0 1 0"/>
    </joint>

    <joint name="caster_joint" type="fixed">
        <!-- ball joint не поддерживается в URDF, заменим на fixed, сохранив положение -->
        <origin xyz="0.8 0 -0.2" rpy="0 0 0"/>
        <parent link="chassis"/>
        <child link="caster"/>
    </joint>

    <joint name="camera_joint" type="fixed">
        <origin xyz="1.0 0 0.25" rpy="0 0 1.5708"/>
        <parent link="chassis"/>
        <child link="camera_link"/>
    </joint>

    <!-- Gazebo плагины и сенсоры -->
    <gazebo>
        <plugin filename="gz-sim-diff-drive-system" name="gz::sim::systems::DiffDrive">
            <child_frame_id>chassis</child_frame_id>
            <publish_odom_tf>true</publish_odom_tf>
            <left_joint>left_wheel_joint</left_joint>
            <right_joint>right_wheel_joint</right_joint>
            <wheel_separation>1.25</wheel_separation>
            <wheel_radius>0.3</wheel_radius>
            <odom_publish_frequency>20</odom_publish_frequency>
            <max_linear_acceleration>1</max_linear_acceleration>
            <min_linear_acceleration>-1</min_linear_acceleration>
            <max_angular_acceleration>2</max_angular_acceleration>
            <min_angular_acceleration>-2</min_angular_acceleration>
            <max_linear_velocity>0.5</max_linear_velocity>
            <min_linear_velocity>-0.5</min_linear_velocity>
            <max_angular_velocity>1</max_angular_velocity>
            <min_angular_velocity>-1</min_angular_velocity>
            <topic>/cmd_vel</topic>
        </plugin>
    </gazebo>

    <!-- gpu_lidar на chassis -->
    <gazebo reference="chassis">
        <sensor name="gpu_lidar" type="gpu_lidar">
            <pose>0.8 0 0.5 0 0 0</pose>
            <topic>lidar</topic>
            <update_rate>10</update_rate>
            <ray>
                <scan>
                    <horizontal>
                        <samples>640</samples>
                        <resolution>1</resolution>
                        <min_angle>-1.396263</min_angle>
                        <max_angle>1.396263</max_angle>
                    </horizontal>
                    <vertical>
                        <samples>1</samples>
                        <resolution>0.01</resolution>
                        <min_angle>0</min_angle>
                        <max_angle>0</max_angle>
                    </vertical>
                </scan>
                <range>
                    <min>0.08</min>
                    <max>10.0</max>
                    <resolution>0.01</resolution>
                </range>
            </ray>
            <always_on>1</always_on>
            <visualize>true</visualize>
        </sensor>
    </gazebo>

    <!-- camera на camera_link -->
    <gazebo reference="camera_link">
        <sensor name="camera_sensor" type="camera">
            <pose>0 0 0 0 0 0</pose>
            <topic>/camera/image_raw</topic>
            <update_rate>30</update_rate>
            <always_on>1</always_on>
            <visualize>1</visualize>
            <camera>
                <horizontal_fov>1.047</horizontal_fov>
                <image>
                    <width>640</width>
                    <height>480</height>
                    <format>R8G8B8</format>
                </image>
                <clip>
                    <near>0.1</near>
                    <far>100</far>
                </clip>
            </camera>
        </sensor>
    </gazebo>

</robot>